2023-10-29 16:41:25,809 ERROR: Exception on /see_user_list [GET] [in /home/marta/miniconda3/envs/hyf_flask_example/lib/python3.10/site-packages/flask/app.py:825]
Traceback (most recent call last):
  File "/home/marta/miniconda3/envs/hyf_flask_example/lib/python3.10/site-packages/sqlalchemy/engine/base.py", line 145, in __init__
    self._dbapi_connection = engine.raw_connection()
  File "/home/marta/miniconda3/envs/hyf_flask_example/lib/python3.10/site-packages/sqlalchemy/engine/base.py", line 3292, in raw_connection
    return self.pool.connect()
  File "/home/marta/miniconda3/envs/hyf_flask_example/lib/python3.10/site-packages/sqlalchemy/pool/base.py", line 452, in connect
    return _ConnectionFairy._checkout(self)
  File "/home/marta/miniconda3/envs/hyf_flask_example/lib/python3.10/site-packages/sqlalchemy/pool/base.py", line 1269, in _checkout
    fairy = _ConnectionRecord.checkout(pool)
  File "/home/marta/miniconda3/envs/hyf_flask_example/lib/python3.10/site-packages/sqlalchemy/pool/base.py", line 716, in checkout
    rec = pool._do_get()
  File "/home/marta/miniconda3/envs/hyf_flask_example/lib/python3.10/site-packages/sqlalchemy/pool/impl.py", line 169, in _do_get
    with util.safe_reraise():
  File "/home/marta/miniconda3/envs/hyf_flask_example/lib/python3.10/site-packages/sqlalchemy/util/langhelpers.py", line 146, in __exit__
    raise exc_value.with_traceback(exc_tb)
  File "/home/marta/miniconda3/envs/hyf_flask_example/lib/python3.10/site-packages/sqlalchemy/pool/impl.py", line 167, in _do_get
    return self._create_connection()
  File "/home/marta/miniconda3/envs/hyf_flask_example/lib/python3.10/site-packages/sqlalchemy/pool/base.py", line 393, in _create_connection
    return _ConnectionRecord(self)
  File "/home/marta/miniconda3/envs/hyf_flask_example/lib/python3.10/site-packages/sqlalchemy/pool/base.py", line 678, in __init__
    self.__connect()
  File "/home/marta/miniconda3/envs/hyf_flask_example/lib/python3.10/site-packages/sqlalchemy/pool/base.py", line 902, in __connect
    with util.safe_reraise():
  File "/home/marta/miniconda3/envs/hyf_flask_example/lib/python3.10/site-packages/sqlalchemy/util/langhelpers.py", line 146, in __exit__
    raise exc_value.with_traceback(exc_tb)
  File "/home/marta/miniconda3/envs/hyf_flask_example/lib/python3.10/site-packages/sqlalchemy/pool/base.py", line 898, in __connect
    self.dbapi_connection = connection = pool._invoke_creator(self)
  File "/home/marta/miniconda3/envs/hyf_flask_example/lib/python3.10/site-packages/sqlalchemy/engine/create.py", line 637, in connect
    return dialect.connect(*cargs, **cparams)
  File "/home/marta/miniconda3/envs/hyf_flask_example/lib/python3.10/site-packages/sqlalchemy/engine/default.py", line 616, in connect
    return self.loaded_dbapi.connect(*cargs, **cparams)
  File "/home/marta/miniconda3/envs/hyf_flask_example/lib/python3.10/site-packages/pymysql/connections.py", line 358, in __init__
    self.connect()
  File "/home/marta/miniconda3/envs/hyf_flask_example/lib/python3.10/site-packages/pymysql/connections.py", line 664, in connect
    self._request_authentication()
  File "/home/marta/miniconda3/envs/hyf_flask_example/lib/python3.10/site-packages/pymysql/connections.py", line 976, in _request_authentication
    auth_packet = _auth.caching_sha2_password_auth(self, auth_packet)
  File "/home/marta/miniconda3/envs/hyf_flask_example/lib/python3.10/site-packages/pymysql/_auth.py", line 240, in caching_sha2_password_auth
    pkt = conn._read_packet()
  File "/home/marta/miniconda3/envs/hyf_flask_example/lib/python3.10/site-packages/pymysql/connections.py", line 772, in _read_packet
    packet.raise_for_error()
  File "/home/marta/miniconda3/envs/hyf_flask_example/lib/python3.10/site-packages/pymysql/protocol.py", line 221, in raise_for_error
    err.raise_mysql_exception(self._data)
  File "/home/marta/miniconda3/envs/hyf_flask_example/lib/python3.10/site-packages/pymysql/err.py", line 143, in raise_mysql_exception
    raise errorclass(errno, errval)
pymysql.err.OperationalError: (1049, "Unknown database 'None'")

The above exception was the direct cause of the following exception:

Traceback (most recent call last):
  File "/home/marta/miniconda3/envs/hyf_flask_example/lib/python3.10/site-packages/flask/app.py", line 1455, in wsgi_app
    response = self.full_dispatch_request()
  File "/home/marta/miniconda3/envs/hyf_flask_example/lib/python3.10/site-packages/flask/app.py", line 869, in full_dispatch_request
    rv = self.handle_user_exception(e)
  File "/home/marta/miniconda3/envs/hyf_flask_example/lib/python3.10/site-packages/flask/app.py", line 867, in full_dispatch_request
    rv = self.dispatch_request()
  File "/home/marta/miniconda3/envs/hyf_flask_example/lib/python3.10/site-packages/flask/app.py", line 852, in dispatch_request
    return self.ensure_sync(self.view_functions[rule.endpoint])(**view_args)
  File "/home/marta/HackYourFuture/HYF_DB_example/app/main/routes_see_data.py", line 21, in see_user_list
    users = User.query.order_by(User.id.asc()).paginate()
  File "/home/marta/miniconda3/envs/hyf_flask_example/lib/python3.10/site-packages/flask_sqlalchemy/query.py", line 98, in paginate
    return QueryPagination(
  File "/home/marta/miniconda3/envs/hyf_flask_example/lib/python3.10/site-packages/flask_sqlalchemy/pagination.py", line 72, in __init__
    items = self._query_items()
  File "/home/marta/miniconda3/envs/hyf_flask_example/lib/python3.10/site-packages/flask_sqlalchemy/pagination.py", line 358, in _query_items
    out = query.limit(self.per_page).offset(self._query_offset).all()
  File "/home/marta/miniconda3/envs/hyf_flask_example/lib/python3.10/site-packages/sqlalchemy/orm/query.py", line 2693, in all
    return self._iter().all()  # type: ignore
  File "/home/marta/miniconda3/envs/hyf_flask_example/lib/python3.10/site-packages/sqlalchemy/orm/query.py", line 2847, in _iter
    result: Union[ScalarResult[_T], Result[_T]] = self.session.execute(
  File "/home/marta/miniconda3/envs/hyf_flask_example/lib/python3.10/site-packages/sqlalchemy/orm/session.py", line 2306, in execute
    return self._execute_internal(
  File "/home/marta/miniconda3/envs/hyf_flask_example/lib/python3.10/site-packages/sqlalchemy/orm/session.py", line 2178, in _execute_internal
    conn = self._connection_for_bind(bind)
  File "/home/marta/miniconda3/envs/hyf_flask_example/lib/python3.10/site-packages/sqlalchemy/orm/session.py", line 2045, in _connection_for_bind
    return trans._connection_for_bind(engine, execution_options)
  File "<string>", line 2, in _connection_for_bind
  File "/home/marta/miniconda3/envs/hyf_flask_example/lib/python3.10/site-packages/sqlalchemy/orm/state_changes.py", line 139, in _go
    ret_value = fn(self, *arg, **kw)
  File "/home/marta/miniconda3/envs/hyf_flask_example/lib/python3.10/site-packages/sqlalchemy/orm/session.py", line 1143, in _connection_for_bind
    conn = bind.connect()
  File "/home/marta/miniconda3/envs/hyf_flask_example/lib/python3.10/site-packages/sqlalchemy/engine/base.py", line 3268, in connect
    return self._connection_cls(self)
  File "/home/marta/miniconda3/envs/hyf_flask_example/lib/python3.10/site-packages/sqlalchemy/engine/base.py", line 147, in __init__
    Connection._handle_dbapi_exception_noconnection(
  File "/home/marta/miniconda3/envs/hyf_flask_example/lib/python3.10/site-packages/sqlalchemy/engine/base.py", line 2430, in _handle_dbapi_exception_noconnection
    raise sqlalchemy_exception.with_traceback(exc_info[2]) from e
  File "/home/marta/miniconda3/envs/hyf_flask_example/lib/python3.10/site-packages/sqlalchemy/engine/base.py", line 145, in __init__
    self._dbapi_connection = engine.raw_connection()
  File "/home/marta/miniconda3/envs/hyf_flask_example/lib/python3.10/site-packages/sqlalchemy/engine/base.py", line 3292, in raw_connection
    return self.pool.connect()
  File "/home/marta/miniconda3/envs/hyf_flask_example/lib/python3.10/site-packages/sqlalchemy/pool/base.py", line 452, in connect
    return _ConnectionFairy._checkout(self)
  File "/home/marta/miniconda3/envs/hyf_flask_example/lib/python3.10/site-packages/sqlalchemy/pool/base.py", line 1269, in _checkout
    fairy = _ConnectionRecord.checkout(pool)
  File "/home/marta/miniconda3/envs/hyf_flask_example/lib/python3.10/site-packages/sqlalchemy/pool/base.py", line 716, in checkout
    rec = pool._do_get()
  File "/home/marta/miniconda3/envs/hyf_flask_example/lib/python3.10/site-packages/sqlalchemy/pool/impl.py", line 169, in _do_get
    with util.safe_reraise():
  File "/home/marta/miniconda3/envs/hyf_flask_example/lib/python3.10/site-packages/sqlalchemy/util/langhelpers.py", line 146, in __exit__
    raise exc_value.with_traceback(exc_tb)
  File "/home/marta/miniconda3/envs/hyf_flask_example/lib/python3.10/site-packages/sqlalchemy/pool/impl.py", line 167, in _do_get
    return self._create_connection()
  File "/home/marta/miniconda3/envs/hyf_flask_example/lib/python3.10/site-packages/sqlalchemy/pool/base.py", line 393, in _create_connection
    return _ConnectionRecord(self)
  File "/home/marta/miniconda3/envs/hyf_flask_example/lib/python3.10/site-packages/sqlalchemy/pool/base.py", line 678, in __init__
    self.__connect()
  File "/home/marta/miniconda3/envs/hyf_flask_example/lib/python3.10/site-packages/sqlalchemy/pool/base.py", line 902, in __connect
    with util.safe_reraise():
  File "/home/marta/miniconda3/envs/hyf_flask_example/lib/python3.10/site-packages/sqlalchemy/util/langhelpers.py", line 146, in __exit__
    raise exc_value.with_traceback(exc_tb)
  File "/home/marta/miniconda3/envs/hyf_flask_example/lib/python3.10/site-packages/sqlalchemy/pool/base.py", line 898, in __connect
    self.dbapi_connection = connection = pool._invoke_creator(self)
  File "/home/marta/miniconda3/envs/hyf_flask_example/lib/python3.10/site-packages/sqlalchemy/engine/create.py", line 637, in connect
    return dialect.connect(*cargs, **cparams)
  File "/home/marta/miniconda3/envs/hyf_flask_example/lib/python3.10/site-packages/sqlalchemy/engine/default.py", line 616, in connect
    return self.loaded_dbapi.connect(*cargs, **cparams)
  File "/home/marta/miniconda3/envs/hyf_flask_example/lib/python3.10/site-packages/pymysql/connections.py", line 358, in __init__
    self.connect()
  File "/home/marta/miniconda3/envs/hyf_flask_example/lib/python3.10/site-packages/pymysql/connections.py", line 664, in connect
    self._request_authentication()
  File "/home/marta/miniconda3/envs/hyf_flask_example/lib/python3.10/site-packages/pymysql/connections.py", line 976, in _request_authentication
    auth_packet = _auth.caching_sha2_password_auth(self, auth_packet)
  File "/home/marta/miniconda3/envs/hyf_flask_example/lib/python3.10/site-packages/pymysql/_auth.py", line 240, in caching_sha2_password_auth
    pkt = conn._read_packet()
  File "/home/marta/miniconda3/envs/hyf_flask_example/lib/python3.10/site-packages/pymysql/connections.py", line 772, in _read_packet
    packet.raise_for_error()
  File "/home/marta/miniconda3/envs/hyf_flask_example/lib/python3.10/site-packages/pymysql/protocol.py", line 221, in raise_for_error
    err.raise_mysql_exception(self._data)
  File "/home/marta/miniconda3/envs/hyf_flask_example/lib/python3.10/site-packages/pymysql/err.py", line 143, in raise_mysql_exception
    raise errorclass(errno, errval)
sqlalchemy.exc.OperationalError: (pymysql.err.OperationalError) (1049, "Unknown database 'None'")
(Background on this error at: https://sqlalche.me/e/20/e3q8)
