2022-03-02 22:34:53,143 ERROR: Exception on /auth/login [POST] [in /home/dx/.conda/envs/hyf_flask_app/lib/python3.7/site-packages/flask/app.py:1761]
Traceback (most recent call last):
  File "/home/dx/.conda/envs/hyf_flask_app/lib/python3.7/site-packages/pymysql/connections.py", line 583, in connect
    **kwargs)
  File "/home/dx/.conda/envs/hyf_flask_app/lib/python3.7/socket.py", line 727, in create_connection
    raise err
  File "/home/dx/.conda/envs/hyf_flask_app/lib/python3.7/socket.py", line 716, in create_connection
    sock.connect(sa)
ConnectionRefusedError: [Errno 111] Connection refused

During handling of the above exception, another exception occurred:

Traceback (most recent call last):
  File "/home/dx/.conda/envs/hyf_flask_app/lib/python3.7/site-packages/sqlalchemy/engine/base.py", line 2158, in _wrap_pool_connect
    return fn()
  File "/home/dx/.conda/envs/hyf_flask_app/lib/python3.7/site-packages/sqlalchemy/pool.py", line 400, in connect
    return _ConnectionFairy._checkout(self)
  File "/home/dx/.conda/envs/hyf_flask_app/lib/python3.7/site-packages/sqlalchemy/pool.py", line 788, in _checkout
    fairy = _ConnectionRecord.checkout(pool)
  File "/home/dx/.conda/envs/hyf_flask_app/lib/python3.7/site-packages/sqlalchemy/pool.py", line 529, in checkout
    rec = pool._do_get()
  File "/home/dx/.conda/envs/hyf_flask_app/lib/python3.7/site-packages/sqlalchemy/pool.py", line 1193, in _do_get
    self._dec_overflow()
  File "/home/dx/.conda/envs/hyf_flask_app/lib/python3.7/site-packages/sqlalchemy/util/langhelpers.py", line 66, in __exit__
    compat.reraise(exc_type, exc_value, exc_tb)
  File "/home/dx/.conda/envs/hyf_flask_app/lib/python3.7/site-packages/sqlalchemy/util/compat.py", line 249, in reraise
    raise value
  File "/home/dx/.conda/envs/hyf_flask_app/lib/python3.7/site-packages/sqlalchemy/pool.py", line 1190, in _do_get
    return self._create_connection()
  File "/home/dx/.conda/envs/hyf_flask_app/lib/python3.7/site-packages/sqlalchemy/pool.py", line 347, in _create_connection
    return _ConnectionRecord(self)
  File "/home/dx/.conda/envs/hyf_flask_app/lib/python3.7/site-packages/sqlalchemy/pool.py", line 474, in __init__
    self.__connect(first_connect_check=True)
  File "/home/dx/.conda/envs/hyf_flask_app/lib/python3.7/site-packages/sqlalchemy/pool.py", line 671, in __connect
    connection = pool._invoke_creator(self)
  File "/home/dx/.conda/envs/hyf_flask_app/lib/python3.7/site-packages/sqlalchemy/engine/strategies.py", line 106, in connect
    return dialect.connect(*cargs, **cparams)
  File "/home/dx/.conda/envs/hyf_flask_app/lib/python3.7/site-packages/sqlalchemy/engine/default.py", line 412, in connect
    return self.dbapi.connect(*cargs, **cparams)
  File "/home/dx/.conda/envs/hyf_flask_app/lib/python3.7/site-packages/pymysql/__init__.py", line 94, in Connect
    return Connection(*args, **kwargs)
  File "/home/dx/.conda/envs/hyf_flask_app/lib/python3.7/site-packages/pymysql/connections.py", line 325, in __init__
    self.connect()
  File "/home/dx/.conda/envs/hyf_flask_app/lib/python3.7/site-packages/pymysql/connections.py", line 630, in connect
    raise exc
pymysql.err.OperationalError: (2003, "Can't connect to MySQL server on 'localhost' ([Errno 111] Connection refused)")

The above exception was the direct cause of the following exception:

Traceback (most recent call last):
  File "/home/dx/.conda/envs/hyf_flask_app/lib/python3.7/site-packages/flask/app.py", line 2292, in wsgi_app
    response = self.full_dispatch_request()
  File "/home/dx/.conda/envs/hyf_flask_app/lib/python3.7/site-packages/flask/app.py", line 1815, in full_dispatch_request
    rv = self.handle_user_exception(e)
  File "/home/dx/.conda/envs/hyf_flask_app/lib/python3.7/site-packages/flask/app.py", line 1718, in handle_user_exception
    reraise(exc_type, exc_value, tb)
  File "/home/dx/.conda/envs/hyf_flask_app/lib/python3.7/site-packages/flask/_compat.py", line 35, in reraise
    raise value
  File "/home/dx/.conda/envs/hyf_flask_app/lib/python3.7/site-packages/flask/app.py", line 1813, in full_dispatch_request
    rv = self.dispatch_request()
  File "/home/dx/.conda/envs/hyf_flask_app/lib/python3.7/site-packages/flask/app.py", line 1799, in dispatch_request
    return self.view_functions[rule.endpoint](**req.view_args)
  File "/home/dx/HYF_DB_example/app/auth/routes.py", line 18, in login
    user = Users.query.filter_by(username=form.username.data).first()
  File "/home/dx/.conda/envs/hyf_flask_app/lib/python3.7/site-packages/sqlalchemy/orm/query.py", line 2895, in first
    ret = list(self[0:1])
  File "/home/dx/.conda/envs/hyf_flask_app/lib/python3.7/site-packages/sqlalchemy/orm/query.py", line 2687, in __getitem__
    return list(res)
  File "/home/dx/.conda/envs/hyf_flask_app/lib/python3.7/site-packages/sqlalchemy/orm/query.py", line 2995, in __iter__
    return self._execute_and_instances(context)
  File "/home/dx/.conda/envs/hyf_flask_app/lib/python3.7/site-packages/sqlalchemy/orm/query.py", line 3016, in _execute_and_instances
    close_with_result=True)
  File "/home/dx/.conda/envs/hyf_flask_app/lib/python3.7/site-packages/sqlalchemy/orm/query.py", line 3025, in _get_bind_args
    **kw
  File "/home/dx/.conda/envs/hyf_flask_app/lib/python3.7/site-packages/sqlalchemy/orm/query.py", line 3007, in _connection_from_session
    conn = self.session.connection(**kw)
  File "/home/dx/.conda/envs/hyf_flask_app/lib/python3.7/site-packages/sqlalchemy/orm/session.py", line 1035, in connection
    execution_options=execution_options)
  File "/home/dx/.conda/envs/hyf_flask_app/lib/python3.7/site-packages/sqlalchemy/orm/session.py", line 1040, in _connection_for_bind
    engine, execution_options)
  File "/home/dx/.conda/envs/hyf_flask_app/lib/python3.7/site-packages/sqlalchemy/orm/session.py", line 409, in _connection_for_bind
    conn = bind.contextual_connect()
  File "/home/dx/.conda/envs/hyf_flask_app/lib/python3.7/site-packages/sqlalchemy/engine/base.py", line 2123, in contextual_connect
    self._wrap_pool_connect(self.pool.connect, None),
  File "/home/dx/.conda/envs/hyf_flask_app/lib/python3.7/site-packages/sqlalchemy/engine/base.py", line 2162, in _wrap_pool_connect
    e, dialect, self)
  File "/home/dx/.conda/envs/hyf_flask_app/lib/python3.7/site-packages/sqlalchemy/engine/base.py", line 1476, in _handle_dbapi_exception_noconnection
    exc_info
  File "/home/dx/.conda/envs/hyf_flask_app/lib/python3.7/site-packages/sqlalchemy/util/compat.py", line 265, in raise_from_cause
    reraise(type(exception), exception, tb=exc_tb, cause=cause)
  File "/home/dx/.conda/envs/hyf_flask_app/lib/python3.7/site-packages/sqlalchemy/util/compat.py", line 248, in reraise
    raise value.with_traceback(tb)
  File "/home/dx/.conda/envs/hyf_flask_app/lib/python3.7/site-packages/sqlalchemy/engine/base.py", line 2158, in _wrap_pool_connect
    return fn()
  File "/home/dx/.conda/envs/hyf_flask_app/lib/python3.7/site-packages/sqlalchemy/pool.py", line 400, in connect
    return _ConnectionFairy._checkout(self)
  File "/home/dx/.conda/envs/hyf_flask_app/lib/python3.7/site-packages/sqlalchemy/pool.py", line 788, in _checkout
    fairy = _ConnectionRecord.checkout(pool)
  File "/home/dx/.conda/envs/hyf_flask_app/lib/python3.7/site-packages/sqlalchemy/pool.py", line 529, in checkout
    rec = pool._do_get()
  File "/home/dx/.conda/envs/hyf_flask_app/lib/python3.7/site-packages/sqlalchemy/pool.py", line 1193, in _do_get
    self._dec_overflow()
  File "/home/dx/.conda/envs/hyf_flask_app/lib/python3.7/site-packages/sqlalchemy/util/langhelpers.py", line 66, in __exit__
    compat.reraise(exc_type, exc_value, exc_tb)
  File "/home/dx/.conda/envs/hyf_flask_app/lib/python3.7/site-packages/sqlalchemy/util/compat.py", line 249, in reraise
    raise value
  File "/home/dx/.conda/envs/hyf_flask_app/lib/python3.7/site-packages/sqlalchemy/pool.py", line 1190, in _do_get
    return self._create_connection()
  File "/home/dx/.conda/envs/hyf_flask_app/lib/python3.7/site-packages/sqlalchemy/pool.py", line 347, in _create_connection
    return _ConnectionRecord(self)
  File "/home/dx/.conda/envs/hyf_flask_app/lib/python3.7/site-packages/sqlalchemy/pool.py", line 474, in __init__
    self.__connect(first_connect_check=True)
  File "/home/dx/.conda/envs/hyf_flask_app/lib/python3.7/site-packages/sqlalchemy/pool.py", line 671, in __connect
    connection = pool._invoke_creator(self)
  File "/home/dx/.conda/envs/hyf_flask_app/lib/python3.7/site-packages/sqlalchemy/engine/strategies.py", line 106, in connect
    return dialect.connect(*cargs, **cparams)
  File "/home/dx/.conda/envs/hyf_flask_app/lib/python3.7/site-packages/sqlalchemy/engine/default.py", line 412, in connect
    return self.dbapi.connect(*cargs, **cparams)
  File "/home/dx/.conda/envs/hyf_flask_app/lib/python3.7/site-packages/pymysql/__init__.py", line 94, in Connect
    return Connection(*args, **kwargs)
  File "/home/dx/.conda/envs/hyf_flask_app/lib/python3.7/site-packages/pymysql/connections.py", line 325, in __init__
    self.connect()
  File "/home/dx/.conda/envs/hyf_flask_app/lib/python3.7/site-packages/pymysql/connections.py", line 630, in connect
    raise exc
sqlalchemy.exc.OperationalError: (pymysql.err.OperationalError) (2003, "Can't connect to MySQL server on 'localhost' ([Errno 111] Connection refused)") (Background on this error at: http://sqlalche.me/e/e3q8)
