2019-03-21 17:19:18,406 ERROR: Exception on /modify_task/1 [POST] [in /home/dx/.conda/envs/hyf_flask_app/lib/python3.7/site-packages/flask/app.py:1761]
Traceback (most recent call last):
  File "/home/dx/.conda/envs/hyf_flask_app/lib/python3.7/site-packages/flask/app.py", line 2292, in wsgi_app
    response = self.full_dispatch_request()
  File "/home/dx/.conda/envs/hyf_flask_app/lib/python3.7/site-packages/flask/app.py", line 1815, in full_dispatch_request
    rv = self.handle_user_exception(e)
  File "/home/dx/.conda/envs/hyf_flask_app/lib/python3.7/site-packages/flask/app.py", line 1718, in handle_user_exception
    reraise(exc_type, exc_value, tb)
  File "/home/dx/.conda/envs/hyf_flask_app/lib/python3.7/site-packages/flask/_compat.py", line 35, in reraise
    raise value
  File "/home/dx/.conda/envs/hyf_flask_app/lib/python3.7/site-packages/flask/app.py", line 1813, in full_dispatch_request
    rv = self.dispatch_request()
  File "/home/dx/.conda/envs/hyf_flask_app/lib/python3.7/site-packages/flask/app.py", line 1799, in dispatch_request
    return self.view_functions[rule.endpoint](**req.view_args)
  File "/home/dx/.conda/envs/hyf_flask_app/lib/python3.7/site-packages/flask_login/utils.py", line 261, in decorated_view
    return func(*args, **kwargs)
  File "/home/dx/kinetics_db-master/app/main/routes_modify_data.py", line 57, in modify_task
    task.status = form.status.data
  File "/home/dx/.conda/envs/hyf_flask_app/lib/python3.7/site-packages/sqlalchemy/orm/attributes.py", line 229, in __set__
    instance_dict(instance), value, None)
  File "/home/dx/.conda/envs/hyf_flask_app/lib/python3.7/site-packages/sqlalchemy/orm/attributes.py", line 815, in set
    value = self.fire_replace_event(state, dict_, value, old, initiator)
  File "/home/dx/.conda/envs/hyf_flask_app/lib/python3.7/site-packages/sqlalchemy/orm/attributes.py", line 835, in fire_replace_event
    state, value, previous, initiator or self._replace_token)
  File "/home/dx/.conda/envs/hyf_flask_app/lib/python3.7/site-packages/sqlalchemy/orm/unitofwork.py", line 88, in set_
    newvalue_state = attributes.instance_state(newvalue)
AttributeError: 'str' object has no attribute '_sa_instance_state'
2019-03-21 17:20:59,034 INFO: Kinetics DB startup [in /home/dx/kinetics_db-master/app/__init__.py:85]
2019-03-21 17:21:23,739 ERROR: Exception on /modify_task/3 [POST] [in /home/dx/.conda/envs/hyf_flask_app/lib/python3.7/site-packages/flask/app.py:1761]
Traceback (most recent call last):
  File "/home/dx/.conda/envs/hyf_flask_app/lib/python3.7/site-packages/flask/app.py", line 2292, in wsgi_app
    response = self.full_dispatch_request()
  File "/home/dx/.conda/envs/hyf_flask_app/lib/python3.7/site-packages/flask/app.py", line 1815, in full_dispatch_request
    rv = self.handle_user_exception(e)
  File "/home/dx/.conda/envs/hyf_flask_app/lib/python3.7/site-packages/flask/app.py", line 1718, in handle_user_exception
    reraise(exc_type, exc_value, tb)
  File "/home/dx/.conda/envs/hyf_flask_app/lib/python3.7/site-packages/flask/_compat.py", line 35, in reraise
    raise value
  File "/home/dx/.conda/envs/hyf_flask_app/lib/python3.7/site-packages/flask/app.py", line 1813, in full_dispatch_request
    rv = self.dispatch_request()
  File "/home/dx/.conda/envs/hyf_flask_app/lib/python3.7/site-packages/flask/app.py", line 1799, in dispatch_request
    return self.view_functions[rule.endpoint](**req.view_args)
  File "/home/dx/.conda/envs/hyf_flask_app/lib/python3.7/site-packages/flask_login/utils.py", line 261, in decorated_view
    return func(*args, **kwargs)
  File "/home/dx/kinetics_db-master/app/main/routes_modify_data.py", line 53, in modify_task
    if form.validate_on_submit():
  File "/home/dx/.conda/envs/hyf_flask_app/lib/python3.7/site-packages/flask_wtf/form.py", line 101, in validate_on_submit
    return self.is_submitted() and self.validate()
  File "/home/dx/.conda/envs/hyf_flask_app/lib/python3.7/site-packages/wtforms/form.py", line 310, in validate
    return super(Form, self).validate(extra)
  File "/home/dx/.conda/envs/hyf_flask_app/lib/python3.7/site-packages/wtforms/form.py", line 152, in validate
    if not field.validate(self, extra):
  File "/home/dx/.conda/envs/hyf_flask_app/lib/python3.7/site-packages/wtforms/fields/core.py", line 206, in validate
    stop_validation = self._run_validation_chain(form, chain)
  File "/home/dx/.conda/envs/hyf_flask_app/lib/python3.7/site-packages/wtforms/fields/core.py", line 226, in _run_validation_chain
    validator(form, self)
  File "/home/dx/kinetics_db-master/app/main/forms.py", line 60, in validate_due_date
    res = re.findall('(\d{2})-(\d{2})-(\d{2})', due_date.data)
  File "/home/dx/.conda/envs/hyf_flask_app/lib/python3.7/re.py", line 223, in findall
    return _compile(pattern, flags).findall(string)
TypeError: expected string or bytes-like object
2019-03-21 17:22:28,456 INFO: Kinetics DB startup [in /home/dx/kinetics_db-master/app/__init__.py:85]
2019-03-21 17:23:09,931 INFO: Kinetics DB startup [in /home/dx/kinetics_db-master/app/__init__.py:85]
2019-03-21 17:24:11,123 INFO: Kinetics DB startup [in /home/dx/kinetics_db-master/app/__init__.py:85]
2019-03-21 17:24:17,529 ERROR: Exception on /modify_task/3 [POST] [in /home/dx/.conda/envs/hyf_flask_app/lib/python3.7/site-packages/flask/app.py:1761]
Traceback (most recent call last):
  File "/home/dx/.conda/envs/hyf_flask_app/lib/python3.7/site-packages/flask/app.py", line 2292, in wsgi_app
    response = self.full_dispatch_request()
  File "/home/dx/.conda/envs/hyf_flask_app/lib/python3.7/site-packages/flask/app.py", line 1815, in full_dispatch_request
    rv = self.handle_user_exception(e)
  File "/home/dx/.conda/envs/hyf_flask_app/lib/python3.7/site-packages/flask/app.py", line 1718, in handle_user_exception
    reraise(exc_type, exc_value, tb)
  File "/home/dx/.conda/envs/hyf_flask_app/lib/python3.7/site-packages/flask/_compat.py", line 35, in reraise
    raise value
  File "/home/dx/.conda/envs/hyf_flask_app/lib/python3.7/site-packages/flask/app.py", line 1813, in full_dispatch_request
    rv = self.dispatch_request()
  File "/home/dx/.conda/envs/hyf_flask_app/lib/python3.7/site-packages/flask/app.py", line 1799, in dispatch_request
    return self.view_functions[rule.endpoint](**req.view_args)
  File "/home/dx/.conda/envs/hyf_flask_app/lib/python3.7/site-packages/flask_login/utils.py", line 261, in decorated_view
    return func(*args, **kwargs)
  File "/home/dx/kinetics_db-master/app/main/routes_modify_data.py", line 53, in modify_task
    if form.validate_on_submit():
  File "/home/dx/.conda/envs/hyf_flask_app/lib/python3.7/site-packages/flask_wtf/form.py", line 101, in validate_on_submit
    return self.is_submitted() and self.validate()
  File "/home/dx/.conda/envs/hyf_flask_app/lib/python3.7/site-packages/wtforms/form.py", line 310, in validate
    return super(Form, self).validate(extra)
  File "/home/dx/.conda/envs/hyf_flask_app/lib/python3.7/site-packages/wtforms/form.py", line 152, in validate
    if not field.validate(self, extra):
  File "/home/dx/.conda/envs/hyf_flask_app/lib/python3.7/site-packages/wtforms/fields/core.py", line 206, in validate
    stop_validation = self._run_validation_chain(form, chain)
  File "/home/dx/.conda/envs/hyf_flask_app/lib/python3.7/site-packages/wtforms/fields/core.py", line 226, in _run_validation_chain
    validator(form, self)
  File "/home/dx/kinetics_db-master/app/main/forms.py", line 62, in validate_due_date
    res = re.findall('(\d{4})-(\d{2})-(\d{2})', due_date.data)
  File "/home/dx/.conda/envs/hyf_flask_app/lib/python3.7/re.py", line 223, in findall
    return _compile(pattern, flags).findall(string)
TypeError: expected string or bytes-like object
2019-03-21 17:24:56,649 INFO: Kinetics DB startup [in /home/dx/kinetics_db-master/app/__init__.py:85]
2019-03-21 17:25:52,266 INFO: Kinetics DB startup [in /home/dx/kinetics_db-master/app/__init__.py:85]
